Workbook

Sheet 2026
A4: PERÍODO DE APURAÇÃO: 2026 | G4: =A4 -> PERÍODO DE APURAÇÃO: 2026 | N4: =G4 -> PERÍODO DE APURAÇÃO: 2026
A5: INVESTIDOR: | G5: =A5 -> INVESTIDOR: | N5: =G5 -> INVESTIDOR:
A6: CPF: | G6: =A6 -> CPF: | N6: =G6 -> CPF:
A8: APURAÇÃO B3 | G8: CONTROLE DE ATIVOS | N8: CONTROLE DE ATIVOS
B10: RESULTADOS EM DAY TRADE (ANUAL) | H10: ATIVOS EM CARTEIRA | P10: DERIVATIVOS EM CARTEIRA
B11: MÊS | C11: PREJUÍZO | D11: LUCRO | E11: SALDO ACUM. | H11: PAPEL | I11: QUANTIDADE | J11: PREÇO MÉDIO | K11: CUSTO TOTAL | L11: RENDIMENTO | P11: VARIÁVEL | Q11: PRÊMIO | R11: TARIFA | S11: VENCIMENTO
B12: PREJUÍZOS ACUMULADOS: | E12: 0
B13: 46023 | C13: =IFERROR(MIN(0,'01.26'!$C$15),0) -> 0 | D13: =IFERROR(MAX(0,'01.26'!$C$15),0) -> 0 | E13: =E12+C13+D13 -> 0
B14: 46054 | C14: =IFERROR(MIN(0,'02.26'!$C$15),0) -> 0 | D14: =IFERROR(MAX(0,'02.26'!$C$15),0) -> 0 | E14: =E13+C14+D14 -> 0
B15: 46082 | C15: =IFERROR(MIN(0,'03.26'!$C$15),0) -> 0 | D15: =IFERROR(MAX(0,'03.26'!$C$15),0) -> 0 | E15: =E14+C15+D15 -> 0
B16: 46113 | C16: =IFERROR(MIN(0,'04.26'!$C$15),0) -> 0 | D16: =IFERROR(MAX(0,'04.26'!$C$15),0) -> 0 | E16: =E15+C16+D16 -> 0
B17: 46143 | C17: =IFERROR(MIN(0,'05.26'!$C$15),0) -> 0 | D17: =IFERROR(MAX(0,'05.26'!$C$15),0) -> 0 | E17: =E16+C17+D17 -> 0
B18: 46174 | C18: =IFERROR(MIN(0,'06.26'!$C$15),0) -> 0 | D18: =IFERROR(MAX(0,'06.26'!$C$15),0) -> 0 | E18: =E17+C18+D18 -> 0
B19: 46204 | C19: =IFERROR(MIN(0,'07.26'!$C$15),0) -> 0 | D19: =IFERROR(MAX(0,'07.26'!$C$15),0) -> 0 | E19: =E18+C19+D19 -> 0
B20: 46235 | C20: =IFERROR(MIN(0,'08.26'!$C$15),0) -> 0 | D20: =IFERROR(MAX(0,'08.26'!$C$15),0) -> 0 | E20: =E19+C20+D20 -> 0
B21: 46266 | C21: =IFERROR(MIN(0,'09.26'!$C$15),0) -> 0 | D21: =IFERROR(MAX(0,'09.26'!$C$15),0) -> 0 | E21: =E20+C21+D21 -> 0
B22: 46296 | C22: =IFERROR(MIN(0,'10.26'!$C$15),0) -> 0 | D22: =IFERROR(MAX(0,'10.26'!$C$15),0) -> 0 | E22: =E21+C22+D22 -> 0
B23: 46327 | C23: =IFERROR(MIN(0,'11.26'!$C$15),0) -> 0 | D23: =IFERROR(MAX(0,'11.26'!$C$15),0) -> 0 | E23: =E22+C23+D23 -> 0
B24: 46357 | C24: =IFERROR(MIN(0,'12.26'!$C$15),0) -> 0 | D24: =IFERROR(MAX(0,'12.26'!$C$15),0) -> 0 | E24: =E23+C24+D24 -> 0
B30: RESULTADOS EM SWING TRADE (ANUAL) | N30: CONTROLE DE ATIVOS
B31: MÊS | C31: PREJUÍZO | D31: LUCRO | E31: SALDO ACUM.
B32: PREJUÍZOS ACUMULADOS: | E32: 0
B33: 46023 | C33: =IFERROR(MIN(0,'01.26'!$B$15),0) -> 0 | D33: =IFERROR(MAX(0,'01.26'!$B$15),0) -> 0 | E33: =E32+C33+D33 -> 0 | O33: OPÇÕES DE MERCADO FUTURO
B34: 46054 | C34: =IFERROR(MIN(0,'02.26'!$B$15),0) -> 0 | D34: =IFERROR(MAX(0,'02.26'!$B$15),0) -> 0 | E34: =E33+C34+D34 -> 0 | O34: OPERAÇÃO | Q34: ATIVO | R34: QUANTIDADE | S34: VALOR | T34: VENCIMENTO
B35: 46082 | C35: =IFERROR(MIN(0,'03.26'!$B$15),0) -> 0 | D35: =IFERROR(MAX(0,'03.26'!$B$15),0) -> 0 | E35: =E34+C35+D35 -> 0
B36: 46113 | C36: =IFERROR(MIN(0,'04.26'!$B$15),0) -> 0 | D36: =IFERROR(MAX(0,'04.26'!$B$15),0) -> 0 | E36: =E35+C36+D36 -> 0
B37: 46143 | C37: =IFERROR(MIN(0,'05.26'!$B$15),0) -> 0 | D37: =IFERROR(MAX(0,'05.26'!$B$15),0) -> 0 | E37: =E36+C37+D37 -> 0
B38: 46174 | C38: =IFERROR(MIN(0,'06.26'!$B$15),0) -> 0 | D38: =IFERROR(MAX(0,'06.26'!$B$15),0) -> 0 | E38: =E37+C38+D38 -> 0
B39: 46204 | C39: =IFERROR(MIN(0,'07.26'!$B$15),0) -> 0 | D39: =IFERROR(MAX(0,'07.26'!$B$15),0) -> 0 | E39: =E38+C39+D39 -> 0
B40: 46235 | C40: =IFERROR(MIN(0,'08.26'!$B$15),0) -> 0 | D40: =IFERROR(MAX(0,'08.26'!$B$15),0) -> 0 | E40: =E39+C40+D40 -> 0
B41: 46266 | C41: =IFERROR(MIN(0,'09.26'!$B$15),0) -> 0 | D41: =IFERROR(MAX(0,'09.26'!$B$15),0) -> 0 | E41: =E40+C41+D41 -> 0
B42: 46296 | C42: =IFERROR(MIN(0,'10.26'!$B$15),0) -> 0 | D42: =IFERROR(MAX(0,'10.26'!$B$15),0) -> 0 | E42: =E41+C42+D42 -> 0
B43: 46327 | C43: =IFERROR(MIN(0,'11.26'!$B$15),0) -> 0 | D43: =IFERROR(MAX(0,'11.26'!$B$15),0) -> 0 | E43: =E42+C43+D43 -> 0
B44: 46357 | C44: =IFERROR(MIN(0,'12.26'!$B$15),0) -> 0 | D44: =IFERROR(MAX(0,'12.26'!$B$15),0) -> 0 | E44: =E43+C44+D44 -> 0 | H44: VALOR TOTAL DE PATRIMÔNIO ACUMULADO: | K44: =SUM(K12:K38) -> 0
A53: =A4 -> PERÍODO DE APURAÇÃO: 2026 | G53: =A4 -> PERÍODO DE APURAÇÃO: 2026 | N53: =G53 -> PERÍODO DE APURAÇÃO: 2026
A54: =A5 -> INVESTIDOR: | G54: =A54 -> INVESTIDOR: | N54: =G54 -> INVESTIDOR:
A55: =A6 -> CPF: | G55: =A55 -> CPF: | N55: =G55 -> CPF:
A57: APURAÇÃO B3 | G57: POSIÇÃO DA CARTEIRA POR ATIVO (MENSAL) | N57: EVOLUÇÃO PATRIMONIAL (ANUAL)
B59: RESULTADOS EM FUNDOS IMOBILIÁRIOS (ANUAL)
B60: MÊS | C60: PREJUÍZO | D60: LUCRO | E60: SALDO ACUM.
...

Sheet 01.26
A6: PERÍODO DE APURAÇÃO: 01.26
A7: INVESTIDOR:
A8: CPF:
A10: OPERAÇÕES RENDA VARIÁVEL
B14: SWING TRADE | C14: DAY TRADE: | F14: Informações complementares:
A15: Mercado à vista - ações:
A16: Mercado à vista - ouro: | F16: Isenção de IR
A18: Mercado de opções: | F18: I. Referente à alienação até R$ 20 mil no mercado à vista
A19: Mercado de opções flexíveis:
A20: Mercado à termo: | G20: Alienações (Vendas) | J20: Ganho Isento
F21: Ação | G21: 0 | J21: 0
A22: Mercado futuro - dólar:
A23: Mercado futuro - índices: | F23: Ouro | G23: 0 | J23: 0
A24: Mercado futuro - juros:
A25: Mercado futuro - outros:
F26: II. Referente à ações de pequenas e médias empresas
A27: RESULTADO LÍQUIDO DO MÊS | B27: =SUM(B15:B25) -> 0 | C27: =SUM(C15:C25) -> 0
A28: Resultado negativo até o mês anterior | B28: ='2026'!E32 -> 0 | C28: ='2026'!E12 -> 0 | G28: Ativos isentos op. ST | J28: Ativos isentos op. DT
A29: BASE DE CÁLCULO DO IMPOSTO: | B29: =MAX(0,B27+B28) -> 0 | C29: =MAX(0,C27+C28) -> 0 | F29: Ação | G29: 0 | J29: 0
A30: Prejuízo à compensar | B30: =MIN(0,B27+B28) -> 0 | C30: =MIN(0,C27+C28) -> 0
A31: ALÍQUOTA DO IMPOSTO (%): | B31: 0.15 | C31: 0.2 | F31: Ouro | G31: 0 | J31: 0
A32: IMPOSTO DEVIDO: | B32: =B29*B31 -> 0 | C32: =C29*C31 -> 0
A34: CONSOLIDAÇÃO DO MÊS
A35: Total do imposto devido: | C35: =B32+C32 -> 0 | F35: IR fonte (lei 11.033)
A36: IR Retido na fonte em day trade no mês:
A37: IR Retido na fonte em day trade nos meses anteriores: | F37: Recolhido apenas se o valor mensal for maior que R$ 1
A38: IR Retido na fonte em day trade à compensar: | C38: =MAX(0,C36+C37-C32) -> 0
A39: IR Retido na fonte em swing trade no mês: | F39: Calculo do mês | I39: 0
A40: IR Retido na fonte em swing trade nos meses anteriores: | F40: Recolhido no mês | I40: 0
A41: IR Retido na fonte em swing trade à compensar: | C41: =MAX(0,C39+C40-B32) -> 0 | F41: Meses anteriores | I41: 0
A42: Imposto à pagar: | C42: =MAX(0,C32-(C36+C37))+MAX(0,B32-(C39+C40)) -> 0 | F42: Compensado | I42: 0
A43: Vencimento em: | C43: =IF($C$42>=10,WORKDAY(EOMONTH(DATE(2000+VALUE(RIGHT($A$6,2)),VALUE(MID($A$6,FIND(": ",$A$6)+2,2)),1),1)+1,-1),"") | F43: À compensar até dezembro | I43: 0
A47: Operações de Fundo de Investimento imobiliário e/ou Fiagros
A49: Resultado líquido do mês: | F49: Detalhamento do IR fonte (lei 11.033)
A50: Valor negativo até o mês anterior: | B50: ='2026'!E61 -> 0
A51: Base de cálculo do imposto: | B51: =MAX(0,B49+B50) -> 0 | F51: Recolhido apenas se o valor mensal for maior que R$ 1
A52: Prejuízo à compensar: | B52: =MIN(0,B49+B50) -> 0
A53: ALÍQUOTA DO IMPOSTO (%): | B53: 0.2 | F53: Calculo do mês | I53: 0
A54: IMPOSTO DEVIDO | B54: =B51*B53 -> 0 | F54: Recolhido no mês | I54: 0
F55: Meses anteriores | I55: 0
...

Sheet 02.26
A6: PERÍODO DE APURAÇÃO: 02.26
A7: INVESTIDOR:
A8: CPF:
A10: OPERAÇÕES RENDA VARIÁVEL
B14: SWING TRADE | C14: DAY TRADE: | F14: Informações complementares:
A15: Mercado à vista - ações:
A16: Mercado à vista - ouro: | F16: Isenção de IR
A18: Mercado de opções: | F18: I. Referente à alienação até R$ 20 mil no mercado à vista
A19: Mercado de opções flexíveis:
A20: Mercado à termo: | G20: Alienações (Vendas) | J20: Ganho Isento
F21: Ação | G21: 0 | J21: 0
A22: Mercado futuro - dólar:
A23: Mercado futuro - índices: | F23: Ouro | G23: 0 | J23: 0
A24: Mercado futuro - juros:
A25: Mercado futuro - outros:
F26: II. Referente à ações de pequenas e médias empresas
A27: RESULTADO LÍQUIDO DO MÊS | B27: =SUM(B15:B25) -> 0 | C27: =SUM(C15:C25) -> 0
A28: Resultado negativo até o mês anterior | B28: ='01.26'!B30 -> 0 | C28: ='01.26'!C30 -> 0 | G28: Ativos isentos op. ST | J28: Ativos isentos op. DT
A29: BASE DE CÁLCULO DO IMPOSTO: | B29: =MAX(0,B27+B28) -> 0 | C29: =MAX(0,C27+C28) -> 0 | F29: Ação | G29: 0 | J29: 0
A30: Prejuízo à compensar | B30: =MIN(0,B27+B28) -> 0 | C30: =MIN(0,C27+C28) -> 0
A31: ALÍQUOTA DO IMPOSTO (%): | B31: 0.15 | C31: 0.2 | F31: Ouro | G31: 0 | J31: 0
A32: IMPOSTO DEVIDO: | B32: =B29*B31 -> 0 | C32: =C29*C31 -> 0
A34: CONSOLIDAÇÃO DO MÊS
A35: Total do imposto devido: | C35: =B32+C32 -> 0 | F35: IR fonte (lei 11.033)
A36: IR Retido na fonte em day trade no mês:
A37: IR Retido na fonte em day trade nos meses anteriores: | C37: ='01.26'!C38 -> 0 | F37: Recolhido apenas se o valor mensal for maior que R$ 1
A38: IR Retido na fonte em day trade à compensar: | C38: =MAX(0,C36+C37-C32) -> 0
A39: IR Retido na fonte em swing trade no mês: | F39: Calculo do mês | I39: 0
A40: IR Retido na fonte em swing trade nos meses anteriores: | C40: ='01.26'!C41 -> 0 | F40: Recolhido no mês | I40: 0
A41: IR Retido na fonte em swing trade à compensar: | C41: =MAX(0,C39+C40-B32) -> 0 | F41: Meses anteriores | I41: 0
A42: Imposto à pagar: | C42: =MAX(0,C32-(C36+C37))+MAX(0,B32-(C39+C40)) -> 0 | F42: Compensado | I42: 0
A43: Vencimento em: | C43: =IF($C$42>=10,WORKDAY(EOMONTH(DATE(2000+VALUE(RIGHT($A$6,2)),VALUE(MID($A$6,FIND(": ",$A$6)+2,2)),1),1)+1,-1),"") | F43: À compensar até dezembro | I43: 0
A47: Operações de Fundo de Investimento imobiliário e/ou Fiagros
A49: Resultado líquido do mês: | F49: Detalhamento do IR fonte (lei 11.033)
A50: Valor negativo até o mês anterior: | B50: ='01.26'!B52 -> 0
A51: Base de cálculo do imposto: | B51: =MAX(0,B49+B50) -> 0 | F51: Recolhido apenas se o valor mensal for maior que R$ 1
A52: Prejuízo à compensar: | B52: =MIN(0,B49+B50) -> 0
A53: ALÍQUOTA DO IMPOSTO (%): | B53: 0.2 | F53: Calculo do mês | I53: 0
A54: IMPOSTO DEVIDO | B54: =B51*B53 -> 0 | F54: Recolhido no mês | I54: 0
F55: Meses anteriores | I55: 0
...

Sheet 03.26
A6: PERÍODO DE APURAÇÃO: 03.26
A7: INVESTIDOR:
A8: CPF:
A10: OPERAÇÕES RENDA VARIÁVEL
B14: SWING TRADE | C14: DAY TRADE: | F14: Informações complementares:
A15: Mercado à vista - ações:
A16: Mercado à vista - ouro: | F16: Isenção de IR
A18: Mercado de opções: | F18: I. Referente à alienação até R$ 20 mil no mercado à vista
A19: Mercado de opções flexíveis:
A20: Mercado à termo: | G20: Alienações (Vendas) | J20: Ganho Isento
F21: Ação | G21: 0 | J21: 0
A22: Mercado futuro - dólar:
A23: Mercado futuro - índices: | F23: Ouro | G23: 0 | J23: 0
A24: Mercado futuro - juros:
A25: Mercado futuro - outros:
F26: II. Referente à ações de pequenas e médias empresas
A27: RESULTADO LÍQUIDO DO MÊS | B27: =SUM(B15:B25) -> 0 | C27: =SUM(C15:C25) -> 0
A28: Resultado negativo até o mês anterior | B28: ='02.26'!B30 -> 0 | C28: ='02.26'!C30 -> 0 | G28: Ativos isentos op. ST | J28: Ativos isentos op. DT
A29: BASE DE CÁLCULO DO IMPOSTO: | B29: =MAX(0,B27+B28) -> 0 | C29: =MAX(0,C27+C28) -> 0 | F29: Ação | G29: 0 | J29: 0
A30: Prejuízo à compensar | B30: =MIN(0,B27+B28) -> 0 | C30: =MIN(0,C27+C28) -> 0
A31: ALÍQUOTA DO IMPOSTO (%): | B31: 0.15 | C31: 0.2 | F31: Ouro | G31: 0 | J31: 0
A32: IMPOSTO DEVIDO: | B32: =B29*B31 -> 0 | C32: =C29*C31 -> 0
A34: CONSOLIDAÇÃO DO MÊS
A35: Total do imposto devido: | C35: =B32+C32 -> 0 | F35: IR fonte (lei 11.033)
A36: IR Retido na fonte em day trade no mês:
A37: IR Retido na fonte em day trade nos meses anteriores: | C37: ='02.26'!C38 -> 0 | F37: Recolhido apenas se o valor mensal for maior que R$ 1
A38: IR Retido na fonte em day trade à compensar: | C38: =MAX(0,C36+C37-C32) -> 0
A39: IR Retido na fonte em swing trade no mês: | F39: Calculo do mês | I39: 0
A40: IR Retido na fonte em swing trade nos meses anteriores: | C40: ='02.26'!C41 -> 0 | F40: Recolhido no mês | I40: 0
A41: IR Retido na fonte em swing trade à compensar: | C41: =MAX(0,C39+C40-B32) -> 0 | F41: Meses anteriores | I41: 0
A42: Imposto à pagar: | C42: =MAX(0,C32-(C36+C37))+MAX(0,B32-(C39+C40)) -> 0 | F42: Compensado | I42: 0
A43: Vencimento em: | C43: =IF($C$42>=10,WORKDAY(EOMONTH(DATE(2000+VALUE(RIGHT($A$6,2)),VALUE(MID($A$6,FIND(": ",$A$6)+2,2)),1),1)+1,-1),"") | F43: À compensar até dezembro | I43: 0
A47: Operações de Fundo de Investimento imobiliário e/ou Fiagros
A49: Resultado líquido do mês: | F49: Detalhamento do IR fonte (lei 11.033)
A50: Valor negativo até o mês anterior: | B50: ='02.26'!B52 -> 0
A51: Base de cálculo do imposto: | B51: =MAX(0,B49+B50) -> 0 | F51: Recolhido apenas se o valor mensal for maior que R$ 1
A52: Prejuízo à compensar: | B52: =MIN(0,B49+B50) -> 0
A53: ALÍQUOTA DO IMPOSTO (%): | B53: 0.2 | F53: Calculo do mês | I53: 0
A54: IMPOSTO DEVIDO | B54: =B51*B53 -> 0 | F54: Recolhido no mês | I54: 0
F55: Meses anteriores | I55: 0
...

Sheet 04.26
A6: PERÍODO DE APURAÇÃO: 04.26
A7: INVESTIDOR:
A8: CPF:
A10: OPERAÇÕES RENDA VARIÁVEL
B14: SWING TRADE | C14: DAY TRADE: | F14: Informações complementares:
A15: Mercado à vista - ações:
A16: Mercado à vista - ouro: | F16: Isenção de IR
A18: Mercado de opções: | F18: I. Referente à alienação até R$ 20 mil no mercado à vista
A19: Mercado de opções flexíveis:
A20: Mercado à termo: | G20: Alienações (Vendas) | J20: Ganho Isento
F21: Ação | G21: 0 | J21: 0
A22: Mercado futuro - dólar:
A23: Mercado futuro - índices: | F23: Ouro | G23: 0 | J23: 0
A24: Mercado futuro - juros:
A25: Mercado futuro - outros:
F26: II. Referente à ações de pequenas e médias empresas
A27: RESULTADO LÍQUIDO DO MÊS | B27: =SUM(B15:B25) -> 0 | C27: =SUM(C15:C25) -> 0
A28: Resultado negativo até o mês anterior | B28: ='03.26'!B30 -> 0 | C28: ='03.26'!C30 -> 0 | G28: Ativos isentos op. ST | J28: Ativos isentos op. DT
A29: BASE DE CÁLCULO DO IMPOSTO: | B29: =MAX(0,B27+B28) -> 0 | C29: =MAX(0,C27+C28) -> 0 | F29: Ação | G29: 0 | J29: 0
A30: Prejuízo à compensar | B30: =MIN(0,B27+B28) -> 0 | C30: =MIN(0,C27+C28) -> 0
A31: ALÍQUOTA DO IMPOSTO (%): | B31: 0.15 | C31: 0.2 | F31: Ouro | G31: 0 | J31: 0
A32: IMPOSTO DEVIDO: | B32: =B29*B31 -> 0 | C32: =C29*C31 -> 0
A34: CONSOLIDAÇÃO DO MÊS
A35: Total do imposto devido: | C35: =B32+C32 -> 0 | F35: IR fonte (lei 11.033)
A36: IR Retido na fonte em day trade no mês:
A37: IR Retido na fonte em day trade nos meses anteriores: | C37: ='03.26'!C38 -> 0 | F37: Recolhido apenas se o valor mensal for maior que R$ 1
A38: IR Retido na fonte em day trade à compensar: | C38: =MAX(0,C36+C37-C32) -> 0
A39: IR Retido na fonte em swing trade no mês: | F39: Calculo do mês | I39: 0
A40: IR Retido na fonte em swing trade nos meses anteriores: | C40: ='03.26'!C41 -> 0 | F40: Recolhido no mês | I40: 0
A41: IR Retido na fonte em swing trade à compensar: | C41: =MAX(0,C39+C40-B32) -> 0 | F41: Meses anteriores | I41: 0
A42: Imposto à pagar: | C42: =MAX(0,C32-(C36+C37))+MAX(0,B32-(C39+C40)) -> 0 | F42: Compensado | I42: 0
A43: Vencimento em: | C43: =IF($C$42>=10,WORKDAY(EOMONTH(DATE(2000+VALUE(RIGHT($A$6,2)),VALUE(MID($A$6,FIND(": ",$A$6)+2,2)),1),1)+1,-1),"") | F43: À compensar até dezembro | I43: 0
A47: Operações de Fundo de Investimento imobiliário e/ou Fiagros
A49: Resultado líquido do mês: | F49: Detalhamento do IR fonte (lei 11.033)
A50: Valor negativo até o mês anterior: | B50: ='03.26'!B52 -> 0
A51: Base de cálculo do imposto: | B51: =MAX(0,B49+B50) -> 0 | F51: Recolhido apenas se o valor mensal for maior que R$ 1
A52: Prejuízo à compensar: | B52: =MIN(0,B49+B50) -> 0
A53: ALÍQUOTA DO IMPOSTO (%): | B53: 0.2 | F53: Calculo do mês | I53: 0
A54: IMPOSTO DEVIDO | B54: =B51*B53 -> 0 | F54: Recolhido no mês | I54: 0
F55: Meses anteriores | I55: 0
...

Sheet 05.26
A6: PERÍODO DE APURAÇÃO: 05.26
A7: INVESTIDOR:
A8: CPF:
A10: OPERAÇÕES RENDA VARIÁVEL
B14: SWING TRADE | C14: DAY TRADE: | F14: Informações complementares:
A15: Mercado à vista - ações:
A16: Mercado à vista - ouro: | F16: Isenção de IR
A18: Mercado de opções: | F18: I. Referente à alienação até R$ 20 mil no mercado à vista
A19: Mercado de opções flexíveis:
A20: Mercado à termo: | G20: Alienações (Vendas) | J20: Ganho Isento
F21: Ação | G21: 0 | J21: 0
A22: Mercado futuro - dólar:
A23: Mercado futuro - índices: | F23: Ouro | G23: 0 | J23: 0
A24: Mercado futuro - juros:
A25: Mercado futuro - outros:
F26: II. Referente à ações de pequenas e médias empresas
A27: RESULTADO LÍQUIDO DO MÊS | B27: =SUM(B15:B25) -> 0 | C27: =SUM(C15:C25) -> 0
A28: Resultado negativo até o mês anterior | B28: ='04.26'!B30 -> 0 | C28: ='04.26'!C30 -> 0 | G28: Ativos isentos op. ST | J28: Ativos isentos op. DT
A29: BASE DE CÁLCULO DO IMPOSTO: | B29: =MAX(0,B27+B28) -> 0 | C29: =MAX(0,C27+C28) -> 0 | F29: Ação | G29: 0 | J29: 0
A30: Prejuízo à compensar | B30: =MIN(0,B27+B28) -> 0 | C30: =MIN(0,C27+C28) -> 0
A31: ALÍQUOTA DO IMPOSTO (%): | B31: 0.15 | C31: 0.2 | F31: Ouro | G31: 0 | J31: 0
A32: IMPOSTO DEVIDO: | B32: =B29*B31 -> 0 | C32: =C29*C31 -> 0
A34: CONSOLIDAÇÃO DO MÊS
A35: Total do imposto devido: | C35: =B32+C32 -> 0 | F35: IR fonte (lei 11.033)
A36: IR Retido na fonte em day trade no mês:
A37: IR Retido na fonte em day trade nos meses anteriores: | C37: ='04.26'!C38 -> 0 | F37: Recolhido apenas se o valor mensal for maior que R$ 1
A38: IR Retido na fonte em day trade à compensar: | C38: =MAX(0,C36+C37-C32) -> 0
A39: IR Retido na fonte em swing trade no mês: | F39: Calculo do mês | I39: 0
A40: IR Retido na fonte em swing trade nos meses anteriores: | C40: ='04.26'!C41 -> 0 | F40: Recolhido no mês | I40: 0
A41: IR Retido na fonte em swing trade à compensar: | C41: =MAX(0,C39+C40-B32) -> 0 | F41: Meses anteriores | I41: 0
A42: Imposto à pagar: | C42: =MAX(0,C32-(C36+C37))+MAX(0,B32-(C39+C40)) -> 0 | F42: Compensado | I42: 0
A43: Vencimento em: | C43: =IF($C$42>=10,WORKDAY(EOMONTH(DATE(2000+VALUE(RIGHT($A$6,2)),VALUE(MID($A$6,FIND(": ",$A$6)+2,2)),1),1)+1,-1),"") | F43: À compensar até dezembro | I43: 0
A47: Operações de Fundo de Investimento imobiliário e/ou Fiagros
A49: Resultado líquido do mês: | F49: Detalhamento do IR fonte (lei 11.033)
A50: Valor negativo até o mês anterior: | B50: ='04.26'!B52 -> 0
A51: Base de cálculo do imposto: | B51: =MAX(0,B49+B50) -> 0 | F51: Recolhido apenas se o valor mensal for maior que R$ 1
A52: Prejuízo à compensar: | B52: =MIN(0,B49+B50) -> 0
A53: ALÍQUOTA DO IMPOSTO (%): | B53: 0.2 | F53: Calculo do mês | I53: 0
A54: IMPOSTO DEVIDO | B54: =B51*B53 -> 0 | F54: Recolhido no mês | I54: 0
F55: Meses anteriores | I55: 0
...

Sheet 06.26
A6: PERÍODO DE APURAÇÃO: 06.26
A7: INVESTIDOR:
A8: CPF:
A10: OPERAÇÕES RENDA VARIÁVEL
B14: SWING TRADE | C14: DAY TRADE: | F14: Informações complementares:
A15: Mercado à vista - ações:
A16: Mercado à vista - ouro: | F16: Isenção de IR
A18: Mercado de opções: | F18: I. Referente à alienação até R$ 20 mil no mercado à vista
A19: Mercado de opções flexíveis:
A20: Mercado à termo: | G20: Alienações (Vendas) | J20: Ganho Isento
F21: Ação | G21: 0 | J21: 0
A22: Mercado futuro - dólar:
A23: Mercado futuro - índices: | F23: Ouro | G23: 0 | J23: 0
A24: Mercado futuro - juros:
A25: Mercado futuro - outros:
F26: II. Referente à ações de pequenas e médias empresas
A27: RESULTADO LÍQUIDO DO MÊS | B27: =SUM(B15:B25) -> 0 | C27: =SUM(C15:C25) -> 0
A28: Resultado negativo até o mês anterior | B28: ='05.26'!B30 -> 0 | C28: ='05.26'!C30 -> 0 | G28: Ativos isentos op. ST | J28: Ativos isentos op. DT
A29: BASE DE CÁLCULO DO IMPOSTO: | B29: =MAX(0,B27+B28) -> 0 | C29: =MAX(0,C27+C28) -> 0 | F29: Ação | G29: 0 | J29: 0
A30: Prejuízo à compensar | B30: =MIN(0,B27+B28) -> 0 | C30: =MIN(0,C27+C28) -> 0
A31: ALÍQUOTA DO IMPOSTO (%): | B31: 0.15 | C31: 0.2 | F31: Ouro | G31: 0 | J31: 0
A32: IMPOSTO DEVIDO: | B32: =B29*B31 -> 0 | C32: =C29*C31 -> 0
A34: CONSOLIDAÇÃO DO MÊS
A35: Total do imposto devido: | C35: =B32+C32 -> 0 | F35: IR fonte (lei 11.033)
A36: IR Retido na fonte em day trade no mês:
A37: IR Retido na fonte em day trade nos meses anteriores: | C37: ='05.26'!C38 -> 0 | F37: Recolhido apenas se o valor mensal for maior que R$ 1
A38: IR Retido na fonte em day trade à compensar: | C38: =MAX(0,C36+C37-C32) -> 0
A39: IR Retido na fonte em swing trade no mês: | F39: Calculo do mês | I39: 0
A40: IR Retido na fonte em swing trade nos meses anteriores: | C40: ='05.26'!C41 -> 0 | F40: Recolhido no mês | I40: 0
A41: IR Retido na fonte em swing trade à compensar: | C41: =MAX(0,C39+C40-B32) -> 0 | F41: Meses anteriores | I41: 0
A42: Imposto à pagar: | C42: =MAX(0,C32-(C36+C37))+MAX(0,B32-(C39+C40)) -> 0 | F42: Compensado | I42: 0
A43: Vencimento em: | C43: =IF($C$42>=10,WORKDAY(EOMONTH(DATE(2000+VALUE(RIGHT($A$6,2)),VALUE(MID($A$6,FIND(": ",$A$6)+2,2)),1),1)+1,-1),"") | F43: À compensar até dezembro | I43: 0
A47: Operações de Fundo de Investimento imobiliário e/ou Fiagros
A49: Resultado líquido do mês: | F49: Detalhamento do IR fonte (lei 11.033)
A50: Valor negativo até o mês anterior: | B50: ='05.26'!B52 -> 0
A51: Base de cálculo do imposto: | B51: =MAX(0,B49+B50) -> 0 | F51: Recolhido apenas se o valor mensal for maior que R$ 1
A52: Prejuízo à compensar: | B52: =MIN(0,B49+B50) -> 0
A53: ALÍQUOTA DO IMPOSTO (%): | B53: 0.2 | F53: Calculo do mês | I53: 0
A54: IMPOSTO DEVIDO | B54: =B51*B53 -> 0 | F54: Recolhido no mês | I54: 0
F55: Meses anteriores | I55: 0
...

Sheet 07.26
A6: PERÍODO DE APURAÇÃO: 07.26
A7: INVESTIDOR:
A8: CPF:
A10: OPERAÇÕES RENDA VARIÁVEL
B14: SWING TRADE | C14: DAY TRADE: | F14: Informações complementares:
A15: Mercado à vista - ações:
A16: Mercado à vista - ouro: | F16: Isenção de IR
A18: Mercado de opções: | F18: I. Referente à alienação até R$ 20 mil no mercado à vista
A19: Mercado de opções flexíveis:
A20: Mercado à termo: | G20: Alienações (Vendas) | J20: Ganho Isento
F21: Ação | G21: 0 | J21: 0
A22: Mercado futuro - dólar:
A23: Mercado futuro - índices: | F23: Ouro | G23: 0 | J23: 0
A24: Mercado futuro - juros:
A25: Mercado futuro - outros:
F26: II. Referente à ações de pequenas e médias empresas
A27: RESULTADO LÍQUIDO DO MÊS | B27: =SUM(B15:B25) -> 0 | C27: =SUM(C15:C25) -> 0
A28: Resultado negativo até o mês anterior | B28: ='06.26'!B30 -> 0 | C28: ='06.26'!C30 -> 0 | G28: Ativos isentos op. ST | J28: Ativos isentos op. DT
A29: BASE DE CÁLCULO DO IMPOSTO: | B29: =MAX(0,B27+B28) -> 0 | C29: =MAX(0,C27+C28) -> 0 | F29: Ação | G29: 0 | J29: 0
A30: Prejuízo à compensar | B30: =MIN(0,B27+B28) -> 0 | C30: =MIN(0,C27+C28) -> 0
A31: ALÍQUOTA DO IMPOSTO (%): | B31: 0.15 | C31: 0.2 | F31: Ouro | G31: 0 | J31: 0
A32: IMPOSTO DEVIDO: | B32: =B29*B31 -> 0 | C32: =C29*C31 -> 0
A34: CONSOLIDAÇÃO DO MÊS
A35: Total do imposto devido: | C35: =B32+C32 -> 0 | F35: IR fonte (lei 11.033)
A36: IR Retido na fonte em day trade no mês:
A37: IR Retido na fonte em day trade nos meses anteriores: | C37: ='06.26'!C38 -> 0 | F37: Recolhido apenas se o valor mensal for maior que R$ 1
A38: IR Retido na fonte em day trade à compensar: | C38: =MAX(0,C36+C37-C32) -> 0
A39: IR Retido na fonte em swing trade no mês: | F39: Calculo do mês | I39: 0
A40: IR Retido na fonte em swing trade nos meses anteriores: | C40: ='06.26'!C41 -> 0 | F40: Recolhido no mês | I40: 0
A41: IR Retido na fonte em swing trade à compensar: | C41: =MAX(0,C39+C40-B32) -> 0 | F41: Meses anteriores | I41: 0
A42: Imposto à pagar: | C42: =MAX(0,C32-(C36+C37))+MAX(0,B32-(C39+C40)) -> 0 | F42: Compensado | I42: 0
A43: Vencimento em: | C43: =IF($C$42>=10,WORKDAY(EOMONTH(DATE(2000+VALUE(RIGHT($A$6,2)),VALUE(MID($A$6,FIND(": ",$A$6)+2,2)),1),1)+1,-1),"") | F43: À compensar até dezembro | I43: 0
A47: Operações de Fundo de Investimento imobiliário e/ou Fiagros
A49: Resultado líquido do mês: | F49: Detalhamento do IR fonte (lei 11.033)
A50: Valor negativo até o mês anterior: | B50: ='06.26'!B52 -> 0
A51: Base de cálculo do imposto: | B51: =MAX(0,B49+B50) -> 0 | F51: Recolhido apenas se o valor mensal for maior que R$ 1
A52: Prejuízo à compensar: | B52: =MIN(0,B49+B50) -> 0
A53: ALÍQUOTA DO IMPOSTO (%): | B53: 0.2 | F53: Calculo do mês | I53: 0
A54: IMPOSTO DEVIDO | B54: =B51*B53 -> 0 | F54: Recolhido no mês | I54: 0
F55: Meses anteriores | I55: 0
...

Sheet 08.26
A6: PERÍODO DE APURAÇÃO: 08.26
A7: INVESTIDOR:
A8: CPF:
A10: OPERAÇÕES RENDA VARIÁVEL
B14: SWING TRADE | C14: DAY TRADE: | F14: Informações complementares:
A15: Mercado à vista - ações:
A16: Mercado à vista - ouro: | F16: Isenção de IR
A18: Mercado de opções: | F18: I. Referente à alienação até R$ 20 mil no mercado à vista
A19: Mercado de opções flexíveis:
A20: Mercado à termo: | G20: Alienações (Vendas) | J20: Ganho Isento
F21: Ação | G21: 0 | J21: 0
A22: Mercado futuro - dólar:
A23: Mercado futuro - índices: | F23: Ouro | G23: 0 | J23: 0
A24: Mercado futuro - juros:
A25: Mercado futuro - outros:
F26: II. Referente à ações de pequenas e médias empresas
A27: RESULTADO LÍQUIDO DO MÊS | B27: =SUM(B15:B25) -> 0 | C27: =SUM(C15:C25) -> 0
A28: Resultado negativo até o mês anterior | B28: ='07.26'!B30 -> 0 | C28: ='07.26'!C30 -> 0 | G28: Ativos isentos op. ST | J28: Ativos isentos op. DT
A29: BASE DE CÁLCULO DO IMPOSTO: | B29: =MAX(0,B27+B28) -> 0 | C29: =MAX(0,C27+C28) -> 0 | F29: Ação | G29: 0 | J29: 0
A30: Prejuízo à compensar | B30: =MIN(0,B27+B28) -> 0 | C30: =MIN(0,C27+C28) -> 0
A31: ALÍQUOTA DO IMPOSTO (%): | B31: 0.15 | C31: 0.2 | F31: Ouro | G31: 0 | J31: 0
A32: IMPOSTO DEVIDO: | B32: =B29*B31 -> 0 | C32: =C29*C31 -> 0
A34: CONSOLIDAÇÃO DO MÊS
A35: Total do imposto devido: | C35: =B32+C32 -> 0 | F35: IR fonte (lei 11.033)
A36: IR Retido na fonte em day trade no mês:
A37: IR Retido na fonte em day trade nos meses anteriores: | C37: ='07.26'!C38 -> 0 | F37: Recolhido apenas se o valor mensal for maior que R$ 1
A38: IR Retido na fonte em day trade à compensar: | C38: =MAX(0,C36+C37-C32) -> 0
A39: IR Retido na fonte em swing trade no mês: | F39: Calculo do mês | I39: 0
A40: IR Retido na fonte em swing trade nos meses anteriores: | C40: ='07.26'!C41 -> 0 | F40: Recolhido no mês | I40: 0
A41: IR Retido na fonte em swing trade à compensar: | C41: =MAX(0,C39+C40-B32) -> 0 | F41: Meses anteriores | I41: 0
A42: Imposto à pagar: | C42: =MAX(0,C32-(C36+C37))+MAX(0,B32-(C39+C40)) -> 0 | F42: Compensado | I42: 0
A43: Vencimento em: | C43: =IF($C$42>=10,WORKDAY(EOMONTH(DATE(2000+VALUE(RIGHT($A$6,2)),VALUE(MID($A$6,FIND(": ",$A$6)+2,2)),1),1)+1,-1),"") | F43: À compensar até dezembro | I43: 0
A47: Operações de Fundo de Investimento imobiliário e/ou Fiagros
A49: Resultado líquido do mês: | F49: Detalhamento do IR fonte (lei 11.033)
A50: Valor negativo até o mês anterior: | B50: ='07.26'!B52 -> 0
A51: Base de cálculo do imposto: | B51: =MAX(0,B49+B50) -> 0 | F51: Recolhido apenas se o valor mensal for maior que R$ 1
A52: Prejuízo à compensar: | B52: =MIN(0,B49+B50) -> 0
A53: ALÍQUOTA DO IMPOSTO (%): | B53: 0.2 | F53: Calculo do mês | I53: 0
A54: IMPOSTO DEVIDO | B54: =B51*B53 -> 0 | F54: Recolhido no mês | I54: 0
F55: Meses anteriores | I55: 0
...

Sheet 09.26
A6: PERÍODO DE APURAÇÃO: 09.26
A7: INVESTIDOR:
A8: CPF:
A10: OPERAÇÕES RENDA VARIÁVEL
B14: SWING TRADE | C14: DAY TRADE: | F14: Informações complementares:
A15: Mercado à vista - ações:
A16: Mercado à vista - ouro: | F16: Isenção de IR
A18: Mercado de opções: | F18: I. Referente à alienação até R$ 20 mil no mercado à vista
A19: Mercado de opções flexíveis:
A20: Mercado à termo: | G20: Alienações (Vendas) | J20: Ganho Isento
F21: Ação | G21: 0 | J21: 0
A22: Mercado futuro - dólar:
A23: Mercado futuro - índices: | F23: Ouro | G23: 0 | J23: 0
A24: Mercado futuro - juros:
A25: Mercado futuro - outros:
F26: II. Referente à ações de pequenas e médias empresas
A27: RESULTADO LÍQUIDO DO MÊS | B27: =SUM(B15:B25) -> 0 | C27: =SUM(C15:C25) -> 0
A28: Resultado negativo até o mês anterior | B28: ='08.26'!B30 -> 0 | C28: ='08.26'!C30 -> 0 | G28: Ativos isentos op. ST | J28: Ativos isentos op. DT
A29: BASE DE CÁLCULO DO IMPOSTO: | B29: =MAX(0,B27+B28) -> 0 | C29: =MAX(0,C27+C28) -> 0 | F29: Ação | G29: 0 | J29: 0
A30: Prejuízo à compensar | B30: =MIN(0,B27+B28) -> 0 | C30: =MIN(0,C27+C28) -> 0
A31: ALÍQUOTA DO IMPOSTO (%): | B31: 0.15 | C31: 0.2 | F31: Ouro | G31: 0 | J31: 0
A32: IMPOSTO DEVIDO: | B32: =B29*B31 -> 0 | C32: =C29*C31 -> 0
A34: CONSOLIDAÇÃO DO MÊS
A35: Total do imposto devido: | C35: =B32+C32 -> 0 | F35: IR fonte (lei 11.033)
A36: IR Retido na fonte em day trade no mês:
A37: IR Retido na fonte em day trade nos meses anteriores: | C37: ='08.26'!C38 -> 0 | F37: Recolhido apenas se o valor mensal for maior que R$ 1
A38: IR Retido na fonte em day trade à compensar: | C38: =MAX(0,C36+C37-C32) -> 0
A39: IR Retido na fonte em swing trade no mês: | F39: Calculo do mês | I39: 0
A40: IR Retido na fonte em swing trade nos meses anteriores: | C40: ='08.26'!C41 -> 0 | F40: Recolhido no mês | I40: 0
A41: IR Retido na fonte em swing trade à compensar: | C41: =MAX(0,C39+C40-B32) -> 0 | F41: Meses anteriores | I41: 0
A42: Imposto à pagar: | C42: =MAX(0,C32-(C36+C37))+MAX(0,B32-(C39+C40)) -> 0 | F42: Compensado | I42: 0
A43: Vencimento em: | C43: =IF($C$42>=10,WORKDAY(EOMONTH(DATE(2000+VALUE(RIGHT($A$6,2)),VALUE(MID($A$6,FIND(": ",$A$6)+2,2)),1),1)+1,-1),"") | F43: À compensar até dezembro | I43: 0
A47: Operações de Fundo de Investimento imobiliário e/ou Fiagros
A49: Resultado líquido do mês: | F49: Detalhamento do IR fonte (lei 11.033)
A50: Valor negativo até o mês anterior: | B50: ='08.26'!B52 -> 0
A51: Base de cálculo do imposto: | B51: =MAX(0,B49+B50) -> 0 | F51: Recolhido apenas se o valor mensal for maior que R$ 1
A52: Prejuízo à compensar: | B52: =MIN(0,B49+B50) -> 0
A53: ALÍQUOTA DO IMPOSTO (%): | B53: 0.2 | F53: Calculo do mês | I53: 0
A54: IMPOSTO DEVIDO | B54: =B51*B53 -> 0 | F54: Recolhido no mês | I54: 0
F55: Meses anteriores | I55: 0
...

Sheet 10.26
A6: PERÍODO DE APURAÇÃO: 10.26
A7: INVESTIDOR:
A8: CPF:
A10: OPERAÇÕES RENDA VARIÁVEL
B14: SWING TRADE | C14: DAY TRADE: | F14: Informações complementares:
A15: Mercado à vista - ações:
A16: Mercado à vista - ouro: | F16: Isenção de IR
A18: Mercado de opções: | F18: I. Referente à alienação até R$ 20 mil no mercado à vista
A19: Mercado de opções flexíveis:
A20: Mercado à termo: | G20: Alienações (Vendas) | J20: Ganho Isento
F21: Ação | G21: 0 | J21: 0
A22: Mercado futuro - dólar:
A23: Mercado futuro - índices: | F23: Ouro | G23: 0 | J23: 0
A24: Mercado futuro - juros:
A25: Mercado futuro - outros:
F26: II. Referente à ações de pequenas e médias empresas
A27: RESULTADO LÍQUIDO DO MÊS | B27: =SUM(B15:B25) -> 0 | C27: =SUM(C15:C25) -> 0
A28: Resultado negativo até o mês anterior | B28: ='09.26'!B30 -> 0 | C28: ='09.26'!C30 -> 0 | G28: Ativos isentos op. ST | J28: Ativos isentos op. DT
A29: BASE DE CÁLCULO DO IMPOSTO: | B29: =MAX(0,B27+B28) -> 0 | C29: =MAX(0,C27+C28) -> 0 | F29: Ação | G29: 0 | J29: 0
A30: Prejuízo à compensar | B30: =MIN(0,B27+B28) -> 0 | C30: =MIN(0,C27+C28) -> 0
A31: ALÍQUOTA DO IMPOSTO (%): | B31: 0.15 | C31: 0.2 | F31: Ouro | G31: 0 | J31: 0
A32: IMPOSTO DEVIDO: | B32: =B29*B31 -> 0 | C32: =C29*C31 -> 0
A34: CONSOLIDAÇÃO DO MÊS
A35: Total do imposto devido: | C35: =B32+C32 -> 0 | F35: IR fonte (lei 11.033)
A36: IR Retido na fonte em day trade no mês:
A37: IR Retido na fonte em day trade nos meses anteriores: | C37: ='09.26'!C38 -> 0 | F37: Recolhido apenas se o valor mensal for maior que R$ 1
A38: IR Retido na fonte em day trade à compensar: | C38: =MAX(0,C36+C37-C32) -> 0
A39: IR Retido na fonte em swing trade no mês: | F39: Calculo do mês | I39: 0
A40: IR Retido na fonte em swing trade nos meses anteriores: | C40: ='09.26'!C41 -> 0 | F40: Recolhido no mês | I40: 0
A41: IR Retido na fonte em swing trade à compensar: | C41: =MAX(0,C39+C40-B32) -> 0 | F41: Meses anteriores | I41: 0
A42: Imposto à pagar: | C42: =MAX(0,C32-(C36+C37))+MAX(0,B32-(C39+C40)) -> 0 | F42: Compensado | I42: 0
A43: Vencimento em: | C43: =IF($C$42>=10,WORKDAY(EOMONTH(DATE(2000+VALUE(RIGHT($A$6,2)),VALUE(MID($A$6,FIND(": ",$A$6)+2,2)),1),1)+1,-1),"") | F43: À compensar até dezembro | I43: 0
A47: Operações de Fundo de Investimento imobiliário e/ou Fiagros
A49: Resultado líquido do mês: | F49: Detalhamento do IR fonte (lei 11.033)
A50: Valor negativo até o mês anterior: | B50: ='09.26'!B52 -> 0
A51: Base de cálculo do imposto: | B51: =MAX(0,B49+B50) -> 0 | F51: Recolhido apenas se o valor mensal for maior que R$ 1
A52: Prejuízo à compensar: | B52: =MIN(0,B49+B50) -> 0
A53: ALÍQUOTA DO IMPOSTO (%): | B53: 0.2 | F53: Calculo do mês | I53: 0
A54: IMPOSTO DEVIDO | B54: =B51*B53 -> 0 | F54: Recolhido no mês | I54: 0
F55: Meses anteriores | I55: 0
...

Sheet 11.26
A6: PERÍODO DE APURAÇÃO: 11.26
A7: INVESTIDOR:
A8: CPF:
A10: OPERAÇÕES RENDA VARIÁVEL
B14: SWING TRADE | C14: DAY TRADE: | F14: Informações complementares:
A15: Mercado à vista - ações:
A16: Mercado à vista - ouro: | F16: Isenção de IR
A18: Mercado de opções: | F18: I. Referente à alienação até R$ 20 mil no mercado à vista
A19: Mercado de opções flexíveis:
A20: Mercado à termo: | G20: Alienações (Vendas) | J20: Ganho Isento
F21: Ação | G21: 0 | J21: 0
A22: Mercado futuro - dólar:
A23: Mercado futuro - índices: | F23: Ouro | G23: 0 | J23: 0
A24: Mercado futuro - juros:
A25: Mercado futuro - outros:
F26: II. Referente à ações de pequenas e médias empresas
A27: RESULTADO LÍQUIDO DO MÊS | B27: =SUM(B15:B25) -> 0 | C27: =SUM(C15:C25) -> 0
A28: Resultado negativo até o mês anterior | B28: ='10.26'!B30 -> 0 | C28: ='10.26'!C30 -> 0 | G28: Ativos isentos op. ST | J28: Ativos isentos op. DT
A29: BASE DE CÁLCULO DO IMPOSTO: | B29: =MAX(0,B27+B28) -> 0 | C29: =MAX(0,C27+C28) -> 0 | F29: Ação | G29: 0 | J29: 0
A30: Prejuízo à compensar | B30: =MIN(0,B27+B28) -> 0 | C30: =MIN(0,C27+C28) -> 0
A31: ALÍQUOTA DO IMPOSTO (%): | B31: 0.15 | C31: 0.2 | F31: Ouro | G31: 0 | J31: 0
A32: IMPOSTO DEVIDO: | B32: =B29*B31 -> 0 | C32: =C29*C31 -> 0
A34: CONSOLIDAÇÃO DO MÊS
A35: Total do imposto devido: | C35: =B32+C32 -> 0 | F35: IR fonte (lei 11.033)
A36: IR Retido na fonte em day trade no mês:
A37: IR Retido na fonte em day trade nos meses anteriores: | C37: ='10.26'!C38 -> 0 | F37: Recolhido apenas se o valor mensal for maior que R$ 1
A38: IR Retido na fonte em day trade à compensar: | C38: =MAX(0,C36+C37-C32) -> 0
A39: IR Retido na fonte em swing trade no mês: | F39: Calculo do mês | I39: 0
A40: IR Retido na fonte em swing trade nos meses anteriores: | C40: ='10.26'!C41 -> 0 | F40: Recolhido no mês | I40: 0
A41: IR Retido na fonte em swing trade à compensar: | C41: =MAX(0,C39+C40-B32) -> 0 | F41: Meses anteriores | I41: 0
A42: Imposto à pagar: | C42: =MAX(0,C32-(C36+C37))+MAX(0,B32-(C39+C40)) -> 0 | F42: Compensado | I42: 0
A43: Vencimento em: | C43: =IF($C$42>=10,WORKDAY(EOMONTH(DATE(2000+VALUE(RIGHT($A$6,2)),VALUE(MID($A$6,FIND(": ",$A$6)+2,2)),1),1)+1,-1),"") | F43: À compensar até dezembro | I43: 0
A47: Operações de Fundo de Investimento imobiliário e/ou Fiagros
A49: Resultado líquido do mês: | F49: Detalhamento do IR fonte (lei 11.033)
A50: Valor negativo até o mês anterior: | B50: ='10.26'!B52 -> 0
A51: Base de cálculo do imposto: | B51: =MAX(0,B49+B50) -> 0 | F51: Recolhido apenas se o valor mensal for maior que R$ 1
A52: Prejuízo à compensar: | B52: =MIN(0,B49+B50) -> 0
A53: ALÍQUOTA DO IMPOSTO (%): | B53: 0.2 | F53: Calculo do mês | I53: 0
A54: IMPOSTO DEVIDO | B54: =B51*B53 -> 0 | F54: Recolhido no mês | I54: 0
F55: Meses anteriores | I55: 0
...

Sheet 12.26
A6: PERÍODO DE APURAÇÃO: 12.26
A7: INVESTIDOR:
A8: CPF:
A10: OPERAÇÕES RENDA VARIÁVEL
B14: SWING TRADE | C14: DAY TRADE: | F14: Informações complementares:
A15: Mercado à vista - ações:
A16: Mercado à vista - ouro: | F16: Isenção de IR
A18: Mercado de opções: | F18: I. Referente à alienação até R$ 20 mil no mercado à vista
A19: Mercado de opções flexíveis:
A20: Mercado à termo: | G20: Alienações (Vendas) | J20: Ganho Isento
F21: Ação | G21: 0 | J21: 0
A22: Mercado futuro - dólar:
A23: Mercado futuro - índices: | F23: Ouro | G23: 0 | J23: 0
A24: Mercado futuro - juros:
A25: Mercado futuro - outros:
F26: II. Referente à ações de pequenas e médias empresas
A27: RESULTADO LÍQUIDO DO MÊS | B27: =SUM(B15:B25) -> 0 | C27: =SUM(C15:C25) -> 0
A28: Resultado negativo até o mês anterior | B28: ='11.26'!B30 -> 0 | C28: ='11.26'!C30 -> 0 | G28: Ativos isentos op. ST | J28: Ativos isentos op. DT
A29: BASE DE CÁLCULO DO IMPOSTO: | B29: =MAX(0,B27+B28) -> 0 | C29: =MAX(0,C27+C28) -> 0 | F29: Ação | G29: 0 | J29: 0
A30: Prejuízo à compensar | B30: =MIN(0,B27+B28) -> 0 | C30: =MIN(0,C27+C28) -> 0
A31: ALÍQUOTA DO IMPOSTO (%): | B31: 0.15 | C31: 0.2 | F31: Ouro | G31: 0 | J31: 0
A32: IMPOSTO DEVIDO: | B32: =B29*B31 -> 0 | C32: =C29*C31 -> 0
A34: CONSOLIDAÇÃO DO MÊS
A35: Total do imposto devido: | C35: =B32+C32 -> 0 | F35: IR fonte (lei 11.033)
A36: IR Retido na fonte em day trade no mês:
A37: IR Retido na fonte em day trade nos meses anteriores: | C37: ='11.26'!C38 -> 0 | F37: Recolhido apenas se o valor mensal for maior que R$ 1
A38: IR Retido na fonte em day trade à compensar: | C38: =MAX(0,C36+C37-C32) -> 0
A39: IR Retido na fonte em swing trade no mês: | F39: Calculo do mês | I39: 0
A40: IR Retido na fonte em swing trade nos meses anteriores: | C40: ='11.26'!C41 -> 0 | F40: Recolhido no mês | I40: 0
A41: IR Retido na fonte em swing trade à compensar: | C41: =MAX(0,C39+C40-B32) -> 0 | F41: Meses anteriores | I41: 0
A42: Imposto à pagar: | C42: =MAX(0,C32-(C36+C37))+MAX(0,B32-(C39+C40)) -> 0 | F42: Compensado | I42: 0
A43: Vencimento em: | C43: =IF($C$42>=10,WORKDAY(EOMONTH(DATE(2000+VALUE(RIGHT($A$6,2)),VALUE(MID($A$6,FIND(": ",$A$6)+2,2)),1),1)+1,-1),"") | F43: À compensar até dezembro | I43: 0
A47: Operações de Fundo de Investimento imobiliário e/ou Fiagros
A49: Resultado líquido do mês: | F49: Detalhamento do IR fonte (lei 11.033)
A50: Valor negativo até o mês anterior: | B50: ='11.26'!B52 -> 0
A51: Base de cálculo do imposto: | B51: =MAX(0,B49+B50) -> 0 | F51: Recolhido apenas se o valor mensal for maior que R$ 1
A52: Prejuízo à compensar: | B52: =MIN(0,B49+B50) -> 0
A53: ALÍQUOTA DO IMPOSTO (%): | B53: 0.2 | F53: Calculo do mês | I53: 0
A54: IMPOSTO DEVIDO | B54: =B51*B53 -> 0 | F54: Recolhido no mês | I54: 0
F55: Meses anteriores | I55: 0
...
